2023-06-22 17:36:43,670 ERROR: Exception on / [GET] [in c:\users\asus\desktop\first_project\venv\lib\site-packages\flask\app.py:1414]
Traceback (most recent call last):
  File "c:\users\asus\desktop\first_project\venv\lib\site-packages\sqlalchemy\engine\base.py", line 1965, in _exec_single_context
    self.dialect.do_execute(
  File "c:\users\asus\desktop\first_project\venv\lib\site-packages\sqlalchemy\engine\default.py", line 921, in do_execute
    cursor.execute(statement, parameters)
  File "c:\users\asus\desktop\first_project\venv\lib\site-packages\MySQLdb\cursors.py", line 206, in execute
    res = self._query(query)
  File "c:\users\asus\desktop\first_project\venv\lib\site-packages\MySQLdb\cursors.py", line 319, in _query
    db.query(q)
  File "c:\users\asus\desktop\first_project\venv\lib\site-packages\MySQLdb\connections.py", line 254, in query
    _mysql.connection.query(self, query)
MySQLdb.ProgrammingError: (1146, "Table 'flask_db_test.user' doesn't exist")

The above exception was the direct cause of the following exception:

Traceback (most recent call last):
  File "c:\users\asus\desktop\first_project\venv\lib\site-packages\flask\app.py", line 2190, in wsgi_app
    response = self.full_dispatch_request()
  File "c:\users\asus\desktop\first_project\venv\lib\site-packages\flask\app.py", line 1486, in full_dispatch_request
    rv = self.handle_user_exception(e)
  File "c:\users\asus\desktop\first_project\venv\lib\site-packages\flask\app.py", line 1482, in full_dispatch_request
    rv = self.preprocess_request()
  File "c:\users\asus\desktop\first_project\venv\lib\site-packages\flask\app.py", line 1974, in preprocess_request
    rv = self.ensure_sync(before_func)()
  File "C:\Users\ASUS\Desktop\first_project\app\main\routes.py", line 14, in before_request
    if current_user.is_authenticated:
  File "c:\users\asus\desktop\first_project\venv\lib\site-packages\werkzeug\local.py", line 311, in __get__
    obj = instance._get_current_object()
  File "c:\users\asus\desktop\first_project\venv\lib\site-packages\werkzeug\local.py", line 515, in _get_current_object
    return get_name(local())  # type: ignore
  File "c:\users\asus\desktop\first_project\venv\lib\site-packages\flask_login\utils.py", line 25, in <lambda>
    current_user = LocalProxy(lambda: _get_user())
  File "c:\users\asus\desktop\first_project\venv\lib\site-packages\flask_login\utils.py", line 372, in _get_user
    current_app.login_manager._load_user()
  File "c:\users\asus\desktop\first_project\venv\lib\site-packages\flask_login\login_manager.py", line 364, in _load_user
    user = self._user_callback(user_id)
  File "C:\Users\ASUS\Desktop\first_project\app\models.py", line 139, in load_user
    return User.query.get(int(id))
  File "<string>", line 2, in get
  File "c:\users\asus\desktop\first_project\venv\lib\site-packages\sqlalchemy\util\deprecations.py", line 386, in warned
    return fn(*args, **kwargs)  # type: ignore[no-any-return]
  File "c:\users\asus\desktop\first_project\venv\lib\site-packages\sqlalchemy\orm\query.py", line 1130, in get
    return self._get_impl(ident, loading.load_on_pk_identity)
  File "c:\users\asus\desktop\first_project\venv\lib\site-packages\sqlalchemy\orm\query.py", line 1139, in _get_impl
    return self.session._get_impl(
  File "c:\users\asus\desktop\first_project\venv\lib\site-packages\sqlalchemy\orm\session.py", line 3663, in _get_impl
    return db_load_fn(
  File "c:\users\asus\desktop\first_project\venv\lib\site-packages\sqlalchemy\orm\loading.py", line 666, in load_on_pk_identity
    session.execute(
  File "c:\users\asus\desktop\first_project\venv\lib\site-packages\sqlalchemy\orm\session.py", line 2225, in execute
    return self._execute_internal(
  File "c:\users\asus\desktop\first_project\venv\lib\site-packages\sqlalchemy\orm\session.py", line 2120, in _execute_internal
    result: Result[Any] = compile_state_cls.orm_execute_statement(
  File "c:\users\asus\desktop\first_project\venv\lib\site-packages\sqlalchemy\orm\context.py", line 293, in orm_execute_statement
    result = conn.execute(
  File "c:\users\asus\desktop\first_project\venv\lib\site-packages\sqlalchemy\engine\base.py", line 1412, in execute
    return meth(
  File "c:\users\asus\desktop\first_project\venv\lib\site-packages\sqlalchemy\sql\elements.py", line 483, in _execute_on_connection
    return connection._execute_clauseelement(
  File "c:\users\asus\desktop\first_project\venv\lib\site-packages\sqlalchemy\engine\base.py", line 1635, in _execute_clauseelement
    ret = self._execute_context(
  File "c:\users\asus\desktop\first_project\venv\lib\site-packages\sqlalchemy\engine\base.py", line 1844, in _execute_context
    return self._exec_single_context(
  File "c:\users\asus\desktop\first_project\venv\lib\site-packages\sqlalchemy\engine\base.py", line 1984, in _exec_single_context
    self._handle_dbapi_exception(
  File "c:\users\asus\desktop\first_project\venv\lib\site-packages\sqlalchemy\engine\base.py", line 2339, in _handle_dbapi_exception
    raise sqlalchemy_exception.with_traceback(exc_info[2]) from e
  File "c:\users\asus\desktop\first_project\venv\lib\site-packages\sqlalchemy\engine\base.py", line 1965, in _exec_single_context
    self.dialect.do_execute(
  File "c:\users\asus\desktop\first_project\venv\lib\site-packages\sqlalchemy\engine\default.py", line 921, in do_execute
    cursor.execute(statement, parameters)
  File "c:\users\asus\desktop\first_project\venv\lib\site-packages\MySQLdb\cursors.py", line 206, in execute
    res = self._query(query)
  File "c:\users\asus\desktop\first_project\venv\lib\site-packages\MySQLdb\cursors.py", line 319, in _query
    db.query(q)
  File "c:\users\asus\desktop\first_project\venv\lib\site-packages\MySQLdb\connections.py", line 254, in query
    _mysql.connection.query(self, query)
sqlalchemy.exc.ProgrammingError: (MySQLdb.ProgrammingError) (1146, "Table 'flask_db_test.user' doesn't exist")
[SQL: SELECT user.id AS user_id, user.username AS user_username, user.email AS user_email, user.password_hash AS user_password_hash, user.about_me AS user_about_me, user.last_seen AS user_last_seen 
FROM user 
WHERE user.id = %s]
[parameters: (6,)]
(Background on this error at: https://sqlalche.me/e/20/f405)
2023-06-22 18:15:29,441 INFO: Microblog startup [in C:\Users\ASUS\Desktop\first_project\app\__init__.py:86]
2023-06-22 18:15:53,268 INFO: Microblog startup [in C:\Users\ASUS\Desktop\first_project\app\__init__.py:86]
2023-06-22 18:16:16,397 INFO: Microblog startup [in C:\Users\ASUS\Desktop\first_project\app\__init__.py:86]
2023-06-22 20:28:25,172 INFO: Microblog startup [in C:\Users\ASUS\Desktop\first_project\app\__init__.py:86]
2023-06-22 20:43:51,674 INFO: Microblog startup [in C:\Users\ASUS\Desktop\first_project\app\__init__.py:89]
2023-06-22 20:44:03,012 INFO: Microblog startup [in C:\Users\ASUS\Desktop\first_project\app\__init__.py:89]
2023-06-22 20:50:05,750 INFO: Microblog startup [in C:\Users\ASUS\Desktop\first_project\app\__init__.py:89]
2023-06-22 20:51:05,558 INFO: Microblog startup [in C:\Users\ASUS\Desktop\first_project\app\__init__.py:89]
2023-06-22 20:51:43,173 INFO: Microblog startup [in C:\Users\ASUS\Desktop\first_project\app\__init__.py:89]
2023-06-22 20:51:54,733 INFO: Microblog startup [in C:\Users\ASUS\Desktop\first_project\app\__init__.py:89]
2023-06-22 20:52:05,177 INFO: Microblog startup [in C:\Users\ASUS\Desktop\first_project\app\__init__.py:89]
2023-06-22 20:52:22,766 INFO: Microblog startup [in C:\Users\ASUS\Desktop\first_project\app\__init__.py:89]
2023-06-22 20:53:36,118 INFO: Microblog startup [in C:\Users\ASUS\Desktop\first_project\app\__init__.py:89]
2023-06-22 21:00:37,816 INFO: Microblog startup [in C:\Users\ASUS\Desktop\first_project\app\__init__.py:89]
2023-06-22 21:00:55,767 INFO: Microblog startup [in C:\Users\ASUS\Desktop\first_project\app\__init__.py:89]
2023-06-22 21:01:08,044 INFO: Microblog startup [in C:\Users\ASUS\Desktop\first_project\app\__init__.py:89]
2023-06-22 21:05:18,579 INFO: Microblog startup [in C:\Users\ASUS\Desktop\first_project\app\__init__.py:89]
2023-06-22 21:05:33,657 ERROR: Exception on /auth/login [GET] [in c:\users\asus\desktop\first_project\venv\lib\site-packages\flask\app.py:1414]
Traceback (most recent call last):
  File "c:\users\asus\desktop\first_project\venv\lib\site-packages\flask\app.py", line 2190, in wsgi_app
    response = self.full_dispatch_request()
  File "c:\users\asus\desktop\first_project\venv\lib\site-packages\flask\app.py", line 1486, in full_dispatch_request
    rv = self.handle_user_exception(e)
  File "c:\users\asus\desktop\first_project\venv\lib\site-packages\flask\app.py", line 1484, in full_dispatch_request
    rv = self.dispatch_request()
  File "c:\users\asus\desktop\first_project\venv\lib\site-packages\flask\app.py", line 1469, in dispatch_request
    return self.ensure_sync(self.view_functions[rule.endpoint])(**view_args)
  File "C:\Users\ASUS\Desktop\first_project\app\auth\routes.py", line 19, in login
    return redirect(url_for('auth.index'))
  File "c:\users\asus\desktop\first_project\venv\lib\site-packages\flask\helpers.py", line 225, in url_for
    return current_app.url_for(
  File "c:\users\asus\desktop\first_project\venv\lib\site-packages\flask\app.py", line 1697, in url_for
    return self.handle_url_build_error(error, endpoint, values)
  File "c:\users\asus\desktop\first_project\venv\lib\site-packages\flask\app.py", line 1686, in url_for
    rv = url_adapter.build(  # type: ignore[union-attr]
  File "c:\users\asus\desktop\first_project\venv\lib\site-packages\werkzeug\routing\map.py", line 950, in build
    raise BuildError(endpoint, values, method, self)
werkzeug.routing.exceptions.BuildError: Could not build url for endpoint 'auth.index'. Did you mean 'auth.login' instead?
2023-06-22 21:08:55,233 INFO: Microblog startup [in C:\Users\ASUS\Desktop\first_project\app\__init__.py:89]
