2023-06-22 17:04:37,096 ERROR: Exception on /index [POST] [in c:\users\asus\desktop\first_project\venv\lib\site-packages\flask\app.py:1414]
Traceback (most recent call last):
  File "c:\users\asus\desktop\first_project\venv\lib\site-packages\flask\app.py", line 2190, in wsgi_app
    response = self.full_dispatch_request()
  File "c:\users\asus\desktop\first_project\venv\lib\site-packages\flask\app.py", line 1486, in full_dispatch_request
    rv = self.handle_user_exception(e)
  File "c:\users\asus\desktop\first_project\venv\lib\site-packages\flask\app.py", line 1484, in full_dispatch_request
    rv = self.dispatch_request()
  File "c:\users\asus\desktop\first_project\venv\lib\site-packages\flask\app.py", line 1469, in dispatch_request
    return self.ensure_sync(self.view_functions[rule.endpoint])(**view_args)
  File "c:\users\asus\desktop\first_project\venv\lib\site-packages\flask_login\utils.py", line 290, in decorated_view
    return current_app.ensure_sync(func)(*args, **kwargs)
  File "C:\Users\ASUS\Desktop\first_project\app\main\routes.py", line 28, in index
    db.session.commit()
  File "c:\users\asus\desktop\first_project\venv\lib\site-packages\sqlalchemy\orm\scoping.py", line 552, in commit
    return self._proxied.commit()
  File "c:\users\asus\desktop\first_project\venv\lib\site-packages\sqlalchemy\orm\session.py", line 1899, in commit
    trans.commit(_to_root=True)
  File "<string>", line 2, in commit
  File "c:\users\asus\desktop\first_project\venv\lib\site-packages\sqlalchemy\orm\state_changes.py", line 136, in _go
    ret_value = fn(self, *arg, **kw)
  File "c:\users\asus\desktop\first_project\venv\lib\site-packages\sqlalchemy\orm\session.py", line 1228, in commit
    self.session.dispatch.after_commit(self.session)
  File "c:\users\asus\desktop\first_project\venv\lib\site-packages\sqlalchemy\event\attr.py", line 378, in __call__
    fn(*args, **kw)
  File "C:\Users\ASUS\Desktop\first_project\app\models.py", line 38, in after_commit
    add_to_index(obj.__tablename__, obj)
  File "C:\Users\ASUS\Desktop\first_project\app\search.py", line 10, in add_to_index
    current_app.elasticsearch.index(index=index, id=model.id, body=payload)
  File "c:\users\asus\desktop\first_project\venv\lib\site-packages\elasticsearch\_sync\client\utils.py", line 414, in wrapped
    return api(*args, **kwargs)
  File "c:\users\asus\desktop\first_project\venv\lib\site-packages\elasticsearch\_sync\client\__init__.py", line 2318, in index
    return self.perform_request(  # type: ignore[return-value]
  File "c:\users\asus\desktop\first_project\venv\lib\site-packages\elasticsearch\_sync\client\_base.py", line 285, in perform_request
    meta, resp_body = self.transport.perform_request(
  File "c:\users\asus\desktop\first_project\venv\lib\site-packages\elastic_transport\_transport.py", line 329, in perform_request
    meta, raw_data = node.perform_request(
  File "c:\users\asus\desktop\first_project\venv\lib\site-packages\elastic_transport\_node\_http_urllib3.py", line 199, in perform_request
    raise err from None
elastic_transport.ConnectionError: Connection error caused by: ConnectionError(Connection error caused by: NewConnectionError(<urllib3.connection.HTTPConnection object at 0x0000022DF33E1670>: Failed to establish a new connection: [WinError 10061] Подключение не установлено, т.к. конечный компьютер отверг запрос на подключение))
2023-06-22 17:10:40,538 INFO: Microblog startup [in C:\Users\ASUS\Desktop\first_project\app\__init__.py:86]
2023-06-22 17:11:06,601 ERROR: Exception on /index [POST] [in c:\users\asus\desktop\first_project\venv\lib\site-packages\flask\app.py:1414]
Traceback (most recent call last):
  File "c:\users\asus\desktop\first_project\venv\lib\site-packages\flask\app.py", line 2190, in wsgi_app
    response = self.full_dispatch_request()
  File "c:\users\asus\desktop\first_project\venv\lib\site-packages\flask\app.py", line 1486, in full_dispatch_request
    rv = self.handle_user_exception(e)
  File "c:\users\asus\desktop\first_project\venv\lib\site-packages\flask\app.py", line 1484, in full_dispatch_request
    rv = self.dispatch_request()
  File "c:\users\asus\desktop\first_project\venv\lib\site-packages\flask\app.py", line 1469, in dispatch_request
    return self.ensure_sync(self.view_functions[rule.endpoint])(**view_args)
  File "c:\users\asus\desktop\first_project\venv\lib\site-packages\flask_login\utils.py", line 290, in decorated_view
    return current_app.ensure_sync(func)(*args, **kwargs)
  File "C:\Users\ASUS\Desktop\first_project\app\main\routes.py", line 28, in index
    db.session.commit()
  File "c:\users\asus\desktop\first_project\venv\lib\site-packages\sqlalchemy\orm\scoping.py", line 552, in commit
    return self._proxied.commit()
  File "c:\users\asus\desktop\first_project\venv\lib\site-packages\sqlalchemy\orm\session.py", line 1899, in commit
    trans.commit(_to_root=True)
  File "<string>", line 2, in commit
  File "c:\users\asus\desktop\first_project\venv\lib\site-packages\sqlalchemy\orm\state_changes.py", line 136, in _go
    ret_value = fn(self, *arg, **kw)
  File "c:\users\asus\desktop\first_project\venv\lib\site-packages\sqlalchemy\orm\session.py", line 1228, in commit
    self.session.dispatch.after_commit(self.session)
  File "c:\users\asus\desktop\first_project\venv\lib\site-packages\sqlalchemy\event\attr.py", line 378, in __call__
    fn(*args, **kw)
  File "C:\Users\ASUS\Desktop\first_project\app\models.py", line 38, in after_commit
    add_to_index(obj.__tablename__, obj)
  File "C:\Users\ASUS\Desktop\first_project\app\search.py", line 10, in add_to_index
    current_app.elasticsearch.index(index=index, id=model.id, body=payload)
  File "c:\users\asus\desktop\first_project\venv\lib\site-packages\elasticsearch\_sync\client\utils.py", line 414, in wrapped
    return api(*args, **kwargs)
  File "c:\users\asus\desktop\first_project\venv\lib\site-packages\elasticsearch\_sync\client\__init__.py", line 2318, in index
    return self.perform_request(  # type: ignore[return-value]
  File "c:\users\asus\desktop\first_project\venv\lib\site-packages\elasticsearch\_sync\client\_base.py", line 285, in perform_request
    meta, resp_body = self.transport.perform_request(
  File "c:\users\asus\desktop\first_project\venv\lib\site-packages\elastic_transport\_transport.py", line 329, in perform_request
    meta, raw_data = node.perform_request(
  File "c:\users\asus\desktop\first_project\venv\lib\site-packages\elastic_transport\_node\_http_urllib3.py", line 199, in perform_request
    raise err from None
elastic_transport.ConnectionError: Connection error caused by: ConnectionError(Connection error caused by: NewConnectionError(<urllib3.connection.HTTPConnection object at 0x000002C9FDF6A3D0>: Failed to establish a new connection: [WinError 10061] Подключение не установлено, т.к. конечный компьютер отверг запрос на подключение))
2023-06-22 17:36:36,752 INFO: Microblog startup [in C:\Users\ASUS\Desktop\first_project\app\__init__.py:86]
