2023-06-23 04:00:41,879 ERROR: Exception on /explore [GET] [in c:\users\asus\desktop\first_project\venv\lib\site-packages\flask\app.py:1414]
Traceback (most recent call last):
  File "c:\users\asus\desktop\first_project\venv\lib\site-packages\sqlalchemy\engine\base.py", line 1965, in _exec_single_context
    self.dialect.do_execute(
  File "c:\users\asus\desktop\first_project\venv\lib\site-packages\sqlalchemy\engine\default.py", line 921, in do_execute
    cursor.execute(statement, parameters)
sqlite3.OperationalError: no such table: post

The above exception was the direct cause of the following exception:

Traceback (most recent call last):
  File "c:\users\asus\desktop\first_project\venv\lib\site-packages\flask\app.py", line 2190, in wsgi_app
    response = self.full_dispatch_request()
  File "c:\users\asus\desktop\first_project\venv\lib\site-packages\flask\app.py", line 1486, in full_dispatch_request
    rv = self.handle_user_exception(e)
  File "c:\users\asus\desktop\first_project\venv\lib\site-packages\flask\app.py", line 1484, in full_dispatch_request
    rv = self.dispatch_request()
  File "c:\users\asus\desktop\first_project\venv\lib\site-packages\flask\app.py", line 1469, in dispatch_request
    return self.ensure_sync(self.view_functions[rule.endpoint])(**view_args)
  File "C:\Users\ASUS\Desktop\first_project\app\main\routes.py", line 119, in explore
    posts = Post.query.order_by(Post.timestamp.desc()).paginate(
  File "c:\users\asus\desktop\first_project\venv\lib\site-packages\flask_sqlalchemy\query.py", line 99, in paginate
    return QueryPagination(
  File "c:\users\asus\desktop\first_project\venv\lib\site-packages\flask_sqlalchemy\pagination.py", line 69, in __init__
    items = self._query_items()
  File "c:\users\asus\desktop\first_project\venv\lib\site-packages\flask_sqlalchemy\pagination.py", line 354, in _query_items
    out = query.limit(self.per_page).offset(self._query_offset).all()
  File "c:\users\asus\desktop\first_project\venv\lib\site-packages\sqlalchemy\orm\query.py", line 2692, in all
    return self._iter().all()  # type: ignore
  File "c:\users\asus\desktop\first_project\venv\lib\site-packages\sqlalchemy\orm\query.py", line 2846, in _iter
    result: Union[ScalarResult[_T], Result[_T]] = self.session.execute(
  File "c:\users\asus\desktop\first_project\venv\lib\site-packages\sqlalchemy\orm\session.py", line 2225, in execute
    return self._execute_internal(
  File "c:\users\asus\desktop\first_project\venv\lib\site-packages\sqlalchemy\orm\session.py", line 2120, in _execute_internal
    result: Result[Any] = compile_state_cls.orm_execute_statement(
  File "c:\users\asus\desktop\first_project\venv\lib\site-packages\sqlalchemy\orm\context.py", line 293, in orm_execute_statement
    result = conn.execute(
  File "c:\users\asus\desktop\first_project\venv\lib\site-packages\sqlalchemy\engine\base.py", line 1412, in execute
    return meth(
  File "c:\users\asus\desktop\first_project\venv\lib\site-packages\sqlalchemy\sql\elements.py", line 483, in _execute_on_connection
    return connection._execute_clauseelement(
  File "c:\users\asus\desktop\first_project\venv\lib\site-packages\sqlalchemy\engine\base.py", line 1635, in _execute_clauseelement
    ret = self._execute_context(
  File "c:\users\asus\desktop\first_project\venv\lib\site-packages\sqlalchemy\engine\base.py", line 1844, in _execute_context
    return self._exec_single_context(
  File "c:\users\asus\desktop\first_project\venv\lib\site-packages\sqlalchemy\engine\base.py", line 1984, in _exec_single_context
    self._handle_dbapi_exception(
  File "c:\users\asus\desktop\first_project\venv\lib\site-packages\sqlalchemy\engine\base.py", line 2339, in _handle_dbapi_exception
    raise sqlalchemy_exception.with_traceback(exc_info[2]) from e
  File "c:\users\asus\desktop\first_project\venv\lib\site-packages\sqlalchemy\engine\base.py", line 1965, in _exec_single_context
    self.dialect.do_execute(
  File "c:\users\asus\desktop\first_project\venv\lib\site-packages\sqlalchemy\engine\default.py", line 921, in do_execute
    cursor.execute(statement, parameters)
sqlalchemy.exc.OperationalError: (sqlite3.OperationalError) no such table: post
[SQL: SELECT post.id AS post_id, post.body AS post_body, post.timestamp AS post_timestamp, post.user_id AS post_user_id 
FROM post ORDER BY post.timestamp DESC
 LIMIT ? OFFSET ?]
[parameters: (5, 0)]
(Background on this error at: https://sqlalche.me/e/20/e3q8)
2023-06-23 04:00:50,054 INFO: Microblog startup [in C:\Users\ASUS\Desktop\first_project\app\__init__.py:79]
2023-06-23 04:01:03,816 INFO: Microblog startup [in C:\Users\ASUS\Desktop\first_project\app\__init__.py:79]
2023-06-23 04:01:18,566 INFO: Microblog startup [in C:\Users\ASUS\Desktop\first_project\app\__init__.py:79]
2023-06-23 04:01:25,258 INFO: Microblog startup [in C:\Users\ASUS\Desktop\first_project\app\__init__.py:79]
2023-06-23 04:01:33,993 INFO: Microblog startup [in C:\Users\ASUS\Desktop\first_project\app\__init__.py:79]
