2023-06-22 21:11:07,548 ERROR: Exception on /api/tokens [POST] [in c:\users\asus\desktop\first_project\venv\lib\site-packages\flask\app.py:1414]
Traceback (most recent call last):
  File "c:\users\asus\desktop\first_project\venv\lib\site-packages\flask\app.py", line 2190, in wsgi_app
    response = self.full_dispatch_request()
  File "c:\users\asus\desktop\first_project\venv\lib\site-packages\flask\app.py", line 1486, in full_dispatch_request
    rv = self.handle_user_exception(e)
  File "c:\users\asus\desktop\first_project\venv\lib\site-packages\flask\app.py", line 1484, in full_dispatch_request
    rv = self.dispatch_request()
  File "c:\users\asus\desktop\first_project\venv\lib\site-packages\flask\app.py", line 1469, in dispatch_request
    return self.ensure_sync(self.view_functions[rule.endpoint])(**view_args)
  File "c:\users\asus\desktop\first_project\venv\lib\site-packages\flask_httpauth.py", line 174, in decorated
    return self.ensure_sync(f)(*args, **kwargs)
  File "C:\Users\ASUS\Desktop\first_project\app\api\tokens.py", line 19, in get_token
    token = g.current_user.get_token()
  File "C:\Users\ASUS\Desktop\first_project\app\models.py", line 179, in get_token
    self.token = base64.b64encode(os.urandom(24)).decode('utf-8')
NameError: name 'os' is not defined
2023-06-22 21:11:54,789 ERROR: Exception on /api/tokens [POST] [in c:\users\asus\desktop\first_project\venv\lib\site-packages\flask\app.py:1414]
Traceback (most recent call last):
  File "c:\users\asus\desktop\first_project\venv\lib\site-packages\flask\app.py", line 2190, in wsgi_app
    response = self.full_dispatch_request()
  File "c:\users\asus\desktop\first_project\venv\lib\site-packages\flask\app.py", line 1486, in full_dispatch_request
    rv = self.handle_user_exception(e)
  File "c:\users\asus\desktop\first_project\venv\lib\site-packages\flask\app.py", line 1484, in full_dispatch_request
    rv = self.dispatch_request()
  File "c:\users\asus\desktop\first_project\venv\lib\site-packages\flask\app.py", line 1469, in dispatch_request
    return self.ensure_sync(self.view_functions[rule.endpoint])(**view_args)
  File "c:\users\asus\desktop\first_project\venv\lib\site-packages\flask_httpauth.py", line 174, in decorated
    return self.ensure_sync(f)(*args, **kwargs)
  File "C:\Users\ASUS\Desktop\first_project\app\api\tokens.py", line 19, in get_token
    token = g.current_user.get_token()
  File "C:\Users\ASUS\Desktop\first_project\app\models.py", line 179, in get_token
    self.token = base64.b64encode(os.urandom(24)).decode('utf-8')
NameError: name 'os' is not defined
2023-06-22 21:13:42,836 ERROR: Exception on /api/tokens [POST] [in c:\users\asus\desktop\first_project\venv\lib\site-packages\flask\app.py:1414]
Traceback (most recent call last):
  File "c:\users\asus\desktop\first_project\venv\lib\site-packages\flask\app.py", line 2190, in wsgi_app
    response = self.full_dispatch_request()
  File "c:\users\asus\desktop\first_project\venv\lib\site-packages\flask\app.py", line 1486, in full_dispatch_request
    rv = self.handle_user_exception(e)
  File "c:\users\asus\desktop\first_project\venv\lib\site-packages\flask\app.py", line 1484, in full_dispatch_request
    rv = self.dispatch_request()
  File "c:\users\asus\desktop\first_project\venv\lib\site-packages\flask\app.py", line 1469, in dispatch_request
    return self.ensure_sync(self.view_functions[rule.endpoint])(**view_args)
  File "c:\users\asus\desktop\first_project\venv\lib\site-packages\flask_httpauth.py", line 174, in decorated
    return self.ensure_sync(f)(*args, **kwargs)
  File "C:\Users\ASUS\Desktop\first_project\app\api\tokens.py", line 19, in get_token
    token = g.current_user.get_token()
  File "C:\Users\ASUS\Desktop\first_project\app\models.py", line 179, in get_token
    self.token = base64.b64encode(os.urandom(24)).decode('utf-8')
NameError: name 'os' is not defined
2023-06-22 21:16:41,336 ERROR: Exception on /api/tokens [POST] [in c:\users\asus\desktop\first_project\venv\lib\site-packages\flask\app.py:1414]
Traceback (most recent call last):
  File "c:\users\asus\desktop\first_project\venv\lib\site-packages\flask\app.py", line 2190, in wsgi_app
    response = self.full_dispatch_request()
  File "c:\users\asus\desktop\first_project\venv\lib\site-packages\flask\app.py", line 1486, in full_dispatch_request
    rv = self.handle_user_exception(e)
  File "c:\users\asus\desktop\first_project\venv\lib\site-packages\flask\app.py", line 1484, in full_dispatch_request
    rv = self.dispatch_request()
  File "c:\users\asus\desktop\first_project\venv\lib\site-packages\flask\app.py", line 1469, in dispatch_request
    return self.ensure_sync(self.view_functions[rule.endpoint])(**view_args)
  File "c:\users\asus\desktop\first_project\venv\lib\site-packages\flask_httpauth.py", line 174, in decorated
    return self.ensure_sync(f)(*args, **kwargs)
  File "C:\Users\ASUS\Desktop\first_project\app\api\tokens.py", line 19, in get_token
    token = g.current_user.get_token()
  File "C:\Users\ASUS\Desktop\first_project\app\models.py", line 179, in get_token
    self.token = base64.b64encode(os.urandom(24)).decode('utf-8')
NameError: name 'os' is not defined
2023-06-22 21:17:53,992 ERROR: Exception on /api/tokens [POST] [in c:\users\asus\desktop\first_project\venv\lib\site-packages\flask\app.py:1414]
Traceback (most recent call last):
  File "c:\users\asus\desktop\first_project\venv\lib\site-packages\flask\app.py", line 2190, in wsgi_app
    response = self.full_dispatch_request()
  File "c:\users\asus\desktop\first_project\venv\lib\site-packages\flask\app.py", line 1486, in full_dispatch_request
    rv = self.handle_user_exception(e)
  File "c:\users\asus\desktop\first_project\venv\lib\site-packages\flask\app.py", line 1484, in full_dispatch_request
    rv = self.dispatch_request()
  File "c:\users\asus\desktop\first_project\venv\lib\site-packages\flask\app.py", line 1469, in dispatch_request
    return self.ensure_sync(self.view_functions[rule.endpoint])(**view_args)
  File "c:\users\asus\desktop\first_project\venv\lib\site-packages\flask_httpauth.py", line 174, in decorated
    return self.ensure_sync(f)(*args, **kwargs)
  File "C:\Users\ASUS\Desktop\first_project\app\api\tokens.py", line 19, in get_token
    token = g.current_user.get_token()
  File "C:\Users\ASUS\Desktop\first_project\app\models.py", line 179, in get_token
    self.token = base64.b64encode(os.urandom(24)).decode('utf-8')
NameError: name 'os' is not defined
2023-06-22 21:21:52,854 INFO: Microblog startup [in C:\Users\ASUS\Desktop\first_project\app\__init__.py:89]
2023-06-22 21:21:59,872 ERROR: Exception on /api/tokens [POST] [in c:\users\asus\desktop\first_project\venv\lib\site-packages\flask\app.py:1414]
Traceback (most recent call last):
  File "c:\users\asus\desktop\first_project\venv\lib\site-packages\flask\app.py", line 2190, in wsgi_app
    response = self.full_dispatch_request()
  File "c:\users\asus\desktop\first_project\venv\lib\site-packages\flask\app.py", line 1486, in full_dispatch_request
    rv = self.handle_user_exception(e)
  File "c:\users\asus\desktop\first_project\venv\lib\site-packages\flask\app.py", line 1484, in full_dispatch_request
    rv = self.dispatch_request()
  File "c:\users\asus\desktop\first_project\venv\lib\site-packages\flask\app.py", line 1469, in dispatch_request
    return self.ensure_sync(self.view_functions[rule.endpoint])(**view_args)
  File "c:\users\asus\desktop\first_project\venv\lib\site-packages\flask_httpauth.py", line 174, in decorated
    return self.ensure_sync(f)(*args, **kwargs)
  File "C:\Users\ASUS\Desktop\first_project\app\api\tokens.py", line 19, in get_token
    token = g.current_user.get_token()
  File "C:\Users\ASUS\Desktop\first_project\app\models.py", line 179, in get_token
    self.token = base64.b64encode(os.urandom(24)).decode('utf-8')
NameError: name 'os' is not defined
2023-06-22 21:22:47,854 INFO: Microblog startup [in C:\Users\ASUS\Desktop\first_project\app\__init__.py:89]
2023-06-22 21:22:54,082 ERROR: Exception on /api/tokens [POST] [in c:\users\asus\desktop\first_project\venv\lib\site-packages\flask\app.py:1414]
Traceback (most recent call last):
  File "c:\users\asus\desktop\first_project\venv\lib\site-packages\flask\app.py", line 2190, in wsgi_app
    response = self.full_dispatch_request()
  File "c:\users\asus\desktop\first_project\venv\lib\site-packages\flask\app.py", line 1486, in full_dispatch_request
    rv = self.handle_user_exception(e)
  File "c:\users\asus\desktop\first_project\venv\lib\site-packages\flask\app.py", line 1484, in full_dispatch_request
    rv = self.dispatch_request()
  File "c:\users\asus\desktop\first_project\venv\lib\site-packages\flask\app.py", line 1469, in dispatch_request
    return self.ensure_sync(self.view_functions[rule.endpoint])(**view_args)
  File "c:\users\asus\desktop\first_project\venv\lib\site-packages\flask_httpauth.py", line 174, in decorated
    return self.ensure_sync(f)(*args, **kwargs)
  File "C:\Users\ASUS\Desktop\first_project\app\api\tokens.py", line 10, in get_token
    token = basic_auth.current_user().get_token()
  File "C:\Users\ASUS\Desktop\first_project\app\models.py", line 179, in get_token
    self.token = base64.b64encode(os.urandom(24)).decode('utf-8')
NameError: name 'os' is not defined
2023-06-22 21:25:50,239 INFO: Microblog startup [in C:\Users\ASUS\Desktop\first_project\app\__init__.py:89]
